[08/Sep/2014 21:01:07] ERROR [django.request:231] Internal Server Error: /admin/core/notice/add/
Traceback (most recent call last):
  File "/Users/wendellpbarreto/.virtualenvs/fotec/lib/python2.7/site-packages/django/core/handlers/base.py", line 111, in get_response
    response = wrapped_callback(request, *callback_args, **callback_kwargs)
  File "/Users/wendellpbarreto/.virtualenvs/fotec/lib/python2.7/site-packages/django/contrib/admin/options.py", line 567, in wrapper
    return self.admin_site.admin_view(view)(*args, **kwargs)
  File "/Users/wendellpbarreto/.virtualenvs/fotec/lib/python2.7/site-packages/django/utils/decorators.py", line 105, in _wrapped_view
    response = view_func(request, *args, **kwargs)
  File "/Users/wendellpbarreto/.virtualenvs/fotec/lib/python2.7/site-packages/django/views/decorators/cache.py", line 52, in _wrapped_view_func
    response = view_func(request, *args, **kwargs)
  File "/Users/wendellpbarreto/.virtualenvs/fotec/lib/python2.7/site-packages/django/contrib/admin/sites.py", line 204, in inner
    return view(request, *args, **kwargs)
  File "/Users/wendellpbarreto/.virtualenvs/fotec/lib/python2.7/site-packages/django/contrib/admin/options.py", line 1437, in add_view
    return self.changeform_view(request, None, form_url, extra_context)
  File "/Users/wendellpbarreto/.virtualenvs/fotec/lib/python2.7/site-packages/django/utils/decorators.py", line 29, in _wrapper
    return bound_func(*args, **kwargs)
  File "/Users/wendellpbarreto/.virtualenvs/fotec/lib/python2.7/site-packages/django/utils/decorators.py", line 105, in _wrapped_view
    response = view_func(request, *args, **kwargs)
  File "/Users/wendellpbarreto/.virtualenvs/fotec/lib/python2.7/site-packages/django/utils/decorators.py", line 25, in bound_func
    return func.__get__(self, type(self))(*args2, **kwargs2)
  File "/Users/wendellpbarreto/.virtualenvs/fotec/lib/python2.7/site-packages/django/db/transaction.py", line 394, in inner
    return func(*args, **kwargs)
  File "/Users/wendellpbarreto/.virtualenvs/fotec/lib/python2.7/site-packages/django/contrib/admin/options.py", line 1388, in changeform_view
    self.save_model(request, new_object, form, not add)
  File "/Users/wendellpbarreto/.virtualenvs/fotec/lib/python2.7/site-packages/django/contrib/admin/options.py", line 1029, in save_model
    obj.save()
  File "/Users/wendellpbarreto/Projects/fotec/system/core/models.py", line 284, in save
    super(Notice, self).save(*args, **kwargs)
  File "/Users/wendellpbarreto/.virtualenvs/fotec/lib/python2.7/site-packages/django/db/models/base.py", line 590, in save
    force_update=force_update, update_fields=update_fields)
  File "/Users/wendellpbarreto/.virtualenvs/fotec/lib/python2.7/site-packages/django/db/models/base.py", line 618, in save_base
    updated = self._save_table(raw, cls, force_insert, force_update, using, update_fields)
  File "/Users/wendellpbarreto/.virtualenvs/fotec/lib/python2.7/site-packages/django/db/models/base.py", line 699, in _save_table
    result = self._do_insert(cls._base_manager, using, fields, update_pk, raw)
  File "/Users/wendellpbarreto/.virtualenvs/fotec/lib/python2.7/site-packages/django/db/models/base.py", line 732, in _do_insert
    using=using, raw=raw)
  File "/Users/wendellpbarreto/.virtualenvs/fotec/lib/python2.7/site-packages/django/db/models/manager.py", line 92, in manager_method
    return getattr(self.get_queryset(), name)(*args, **kwargs)
  File "/Users/wendellpbarreto/.virtualenvs/fotec/lib/python2.7/site-packages/django/db/models/query.py", line 921, in _insert
    return query.get_compiler(using=using).execute_sql(return_id)
  File "/Users/wendellpbarreto/.virtualenvs/fotec/lib/python2.7/site-packages/django/db/models/sql/compiler.py", line 920, in execute_sql
    cursor.execute(sql, params)
  File "/Users/wendellpbarreto/.virtualenvs/fotec/lib/python2.7/site-packages/django/db/backends/utils.py", line 81, in execute
    return super(CursorDebugWrapper, self).execute(sql, params)
  File "/Users/wendellpbarreto/.virtualenvs/fotec/lib/python2.7/site-packages/django/db/backends/utils.py", line 65, in execute
    return self.cursor.execute(sql, params)
  File "/Users/wendellpbarreto/.virtualenvs/fotec/lib/python2.7/site-packages/django/db/utils.py", line 94, in __exit__
    six.reraise(dj_exc_type, dj_exc_value, traceback)
  File "/Users/wendellpbarreto/.virtualenvs/fotec/lib/python2.7/site-packages/django/db/backends/utils.py", line 65, in execute
    return self.cursor.execute(sql, params)
IntegrityError: null value in column "photographer_id" violates not-null constraint
DETAIL:  Failing row contains (2, notice, 0, 0, 0, t, t, 2003-06-01, 2014-09-09 00:01:07.425139+00, Fugiat eos beatae accusamus iure dignissimos sunt blanditiis s, Molestiae ut eiusmod quia ullam suscipit est voluptates, <p>qweqwe</p>
, 1, 2, 2, 3, news/o1351169_X4bJVwT.jpg, null).

[08/Sep/2014 21:05:42] INFO [system.core.generic_view:171] Template loaded: gui/home.html
[08/Sep/2014 21:14:53] INFO [system.core.generic_view:171] Template loaded: gui/events.html
[08/Sep/2014 21:14:58] INFO [system.core.generic_view:171] Template loaded: gui/event.html
